Reading in exome psam file...
Reading in population files...
Progressing through phenotypes...
Traceback (most recent call last):
  File "make_exome_phenotype_info.py", line 25, in <module>
    phe_data = pd.read_csv(phe_info[-1], sep='\t', header=None, names=['#FID','IID','PHENO'], dtype='str')
  File "/home/users/guhan/.local/lib/python2.7/site-packages/pandas/io/parsers.py", line 702, in parser_f
    return _read(filepath_or_buffer, kwds)
  File "/home/users/guhan/.local/lib/python2.7/site-packages/pandas/io/parsers.py", line 429, in _read
    parser = TextFileReader(filepath_or_buffer, **kwds)
  File "/home/users/guhan/.local/lib/python2.7/site-packages/pandas/io/parsers.py", line 895, in __init__
    self._make_engine(self.engine)
  File "/home/users/guhan/.local/lib/python2.7/site-packages/pandas/io/parsers.py", line 1122, in _make_engine
    self._engine = CParserWrapper(self.f, **self.options)
  File "/home/users/guhan/.local/lib/python2.7/site-packages/pandas/io/parsers.py", line 1853, in __init__
    self._reader = parsers.TextReader(src, **kwds)
  File "pandas/_libs/parsers.pyx", line 387, in pandas._libs.parsers.TextReader.__cinit__
  File "pandas/_libs/parsers.pyx", line 705, in pandas._libs.parsers.TextReader._setup_parser_source
IOError: [Errno 2] File /oak/stanford/groups/mrivas/ukbb24983/phenotypedata/extras/highconfidenceqc/v2_2020/phe/HC446.phe does not exist: '/oak/stanford/groups/mrivas/ukbb24983/phenotypedata/extras/highconfidenceqc/v2_2020/phe/HC446.phe'
